[32m2024-05-24 23:06:32 +0000[0m - dagster - [34mDEBUG[0m - __ASSET_JOB - a0ad1af4-d46e-4f72-a519-f1afc40b1356 - 6803 - LOGS_CAPTURED - Started capturing logs in process (pid: 6803).
[32m2024-05-24 23:06:32 +0000[0m - dagster - [34mDEBUG[0m - __ASSET_JOB - a0ad1af4-d46e-4f72-a519-f1afc40b1356 - 6803 - finnhub_US_stocks.import_stocks_def - STEP_START - Started execution of step "finnhub_US_stocks.import_stocks_def".
[32m2024-05-24 23:06:34 +0000[0m - dagster - [34mERROR[0m - [31m__ASSET_JOB - a0ad1af4-d46e-4f72-a519-f1afc40b1356 - 6803 - finnhub_US_stocks.import_stocks_def - STEP_FAILURE - Execution of step "finnhub_US_stocks.import_stocks_def" failed.

dagster._core.errors.DagsterExecutionStepExecutionError: Error occurred while executing op "finnhub_US_stocks.import_stocks_def"::

NameError: name 'context' is not defined

Stack Trace:
  File "/workspace/.pyenv_mirror/user/current/lib/python3.12/site-packages/dagster/_core/execution/plan/utils.py", line 54, in op_execution_error_boundary
    yield
  File "/workspace/.pyenv_mirror/user/current/lib/python3.12/site-packages/dagster/_utils/__init__.py", line 468, in iterate_with_context
    next_output = next(iterator)
                  ^^^^^^^^^^^^^^
  File "/workspace/.pyenv_mirror/user/current/lib/python3.12/site-packages/dagster/_core/execution/plan/compute_generator.py", line 141, in _coerce_op_compute_fn_to_iterator
    result = invoke_compute_fn(
             ^^^^^^^^^^^^^^^^^^
  File "/workspace/.pyenv_mirror/user/current/lib/python3.12/site-packages/dagster/_core/execution/plan/compute_generator.py", line 129, in invoke_compute_fn
    return fn(context, **args_to_pass) if context_arg_provided else fn(**args_to_pass)
                                                                    ^^^^^^^^^^^^^^^^^^
  File "/workspace/practical-data-engineering/finnhub-batch-stock-pipeline/finnhub_batch_stock_pipeline/assets/graph_raw.py", line 23, in import_stocks_def
    context.add_output_metadata(
    ^^^^^^^
[0m
