[32m2024-06-15 13:48:06 +0000[0m - dagster - [34mDEBUG[0m - __ASSET_JOB - 0dfb4247-a2ad-4642-9874-036c87f7f86d - 189997 - LOGS_CAPTURED - Started capturing logs in process (pid: 189997).
[32m2024-06-15 13:48:06 +0000[0m - dagster - [34mDEBUG[0m - __ASSET_JOB - 0dfb4247-a2ad-4642-9874-036c87f7f86d - 189997 - spark_operator.create_stock_tables[stock_AAIGF] - STEP_START - Started execution of step "spark_operator.create_stock_tables[stock_AAIGF]".
[32m2024-06-15 13:48:07 +0000[0m - dagster - [34mDEBUG[0m - __ASSET_JOB - 0dfb4247-a2ad-4642-9874-036c87f7f86d - spark_operator.create_stock_tables[stock_AAIGF] - Loading file from: /workspaces/practical-data-engineering/finnhub-batch-stock-pipeline/tmpoagzo_ny/storage/0dfb4247-a2ad-4642-9874-036c87f7f86d/spark_operator.stock_tables/result/stock_AAIGF using PickledObjectFilesystemIOManager...
[32m2024-06-15 13:48:07 +0000[0m - dagster - [34mDEBUG[0m - __ASSET_JOB - 0dfb4247-a2ad-4642-9874-036c87f7f86d - 189997 - spark_operator.create_stock_tables[stock_AAIGF] - LOADED_INPUT - Loaded input "input_fn" using input manager "io_manager", from output "result" of step "spark_operator.stock_tables"
[32m2024-06-15 13:48:07 +0000[0m - dagster - [34mDEBUG[0m - __ASSET_JOB - 0dfb4247-a2ad-4642-9874-036c87f7f86d - 189997 - spark_operator.create_stock_tables[stock_AAIGF] - STEP_INPUT - Got input "input_fn" of type "Any". (Type check passed).
24/06/15 13:48:16 WARN Utils: Your hostname, codespaces-e7c8c2 resolves to a loopback address: 127.0.0.1; using 172.16.5.4 instead (on interface eth0)
24/06/15 13:48:16 WARN Utils: Set SPARK_LOCAL_IP if you need to bind to another address
24/06/15 13:48:19 WARN NativeCodeLoader: Unable to load native-hadoop library for your platform... using builtin-java classes where applicable
Setting default log level to "WARN".
To adjust logging level use sc.setLogLevel(newLevel). For SparkR, use setLogLevel(newLevel).
24/06/15 13:48:26 WARN Utils: Service 'SparkUI' could not bind on port 4040. Attempting port 4041.
24/06/15 13:48:26 WARN Utils: Service 'SparkUI' could not bind on port 4041. Attempting port 4042.
24/06/15 13:48:37 WARN GarbageCollectionMetrics: To enable non-built-in garbage collector(s) List(G1 Concurrent GC), users should configure it(them) to spark.eventLog.gcMetrics.youngGenerationGarbageCollectors or spark.eventLog.gcMetrics.oldGenerationGarbageCollectors
ERROR:root:Exception while sending command.
Traceback (most recent call last):
  File "/usr/local/python/3.10.13/lib/python3.10/site-packages/py4j/clientserver.py", line 511, in send_command
    answer = smart_decode(self.stream.readline()[:-1])
RuntimeError: reentrant call inside <_io.BufferedReader name=12>

During handling of the above exception, another exception occurred:

Traceback (most recent call last):
  File "/usr/local/python/3.10.13/lib/python3.10/site-packages/py4j/java_gateway.py", line 1038, in send_command
    response = connection.send_command(command)
  File "/usr/local/python/3.10.13/lib/python3.10/site-packages/py4j/clientserver.py", line 539, in send_command
    raise Py4JNetworkError(
py4j.protocol.Py4JNetworkError: Error while sending or receiving
ERROR:root:Exception while sending command.
Traceback (most recent call last):
  File "/usr/local/python/3.10.13/lib/python3.10/site-packages/py4j/clientserver.py", line 511, in send_command
    answer = smart_decode(self.stream.readline()[:-1])
  File "/usr/local/python/3.10.13/lib/python3.10/socket.py", line 705, in readinto
    return self._sock.recv_into(b)
  File "/usr/local/python/3.10.13/lib/python3.10/site-packages/pyspark/context.py", line 381, in signal_handler
    self.cancelAllJobs()
  File "/usr/local/python/3.10.13/lib/python3.10/site-packages/pyspark/context.py", line 2446, in cancelAllJobs
    self._jsc.sc().cancelAllJobs()
  File "/usr/local/python/3.10.13/lib/python3.10/site-packages/py4j/java_gateway.py", line 1322, in __call__
    return_value = get_return_value(
  File "/usr/local/python/3.10.13/lib/python3.10/site-packages/pyspark/errors/exceptions/captured.py", line 179, in deco
    return f(*a, **kw)
  File "/usr/local/python/3.10.13/lib/python3.10/site-packages/py4j/protocol.py", line 334, in get_return_value
    raise Py4JError(
py4j.protocol.Py4JError: An error occurred while calling o35.sc

During handling of the above exception, another exception occurred:

Traceback (most recent call last):
  File "/usr/local/python/3.10.13/lib/python3.10/site-packages/py4j/java_gateway.py", line 1038, in send_command
    response = connection.send_command(command)
  File "/usr/local/python/3.10.13/lib/python3.10/site-packages/py4j/clientserver.py", line 539, in send_command
    raise Py4JNetworkError(
py4j.protocol.Py4JNetworkError: Error while sending or receiving
[32m2024-06-15 13:49:05 +0000[0m - dagster - [34mINFO[0m - __ASSET_JOB - 0dfb4247-a2ad-4642-9874-036c87f7f86d - spark_operator.create_stock_tables[stock_AAIGF] - Pyspark Error: An error occurred while calling o51.json
[32m2024-06-15 13:49:05 +0000[0m - dagster - [34mDEBUG[0m - __ASSET_JOB - 0dfb4247-a2ad-4642-9874-036c87f7f86d - 189997 - spark_operator.create_stock_tables[stock_AAIGF] - STEP_OUTPUT - Yielded output "metric_and_series" of type "Any". (Type check passed).
[32m2024-06-15 13:49:06 +0000[0m - dagster - [34mDEBUG[0m - __ASSET_JOB - 0dfb4247-a2ad-4642-9874-036c87f7f86d - spark_operator.create_stock_tables[stock_AAIGF] - Writing S3 object at: s3a://dagster-api/staging/2024-06-15/spark_operator.create_stock_tables[stock_AAIGF]/metric_and_series
[32m2024-06-15 13:49:06 +0000[0m - dagster - [34mWARNING[0m - __ASSET_JOB - 0dfb4247-a2ad-4642-9874-036c87f7f86d - spark_operator.create_stock_tables[stock_AAIGF] - Removing existing S3 object: staging/2024-06-15/spark_operator.create_stock_tables[stock_AAIGF]/metric_and_series
[32m2024-06-15 13:49:06 +0000[0m - dagster - [34mDEBUG[0m - __ASSET_JOB - 0dfb4247-a2ad-4642-9874-036c87f7f86d - 189997 - spark_operator.create_stock_tables[stock_AAIGF] - STEP_UP_FOR_RETRY - Execution of step "spark_operator.create_stock_tables[stock_AAIGF]" failed and has requested a retry in 0.33532649955459104 seconds.

dagster._core.execution.plan.utils.RetryRequestedFromPolicy

Stack Trace:
  File "/usr/local/python/3.10.13/lib/python3.10/site-packages/dagster/_core/execution/plan/execute_plan.py", line 282, in dagster_event_sequence_for_step
    for step_event in check.generator(step_events):
  File "/usr/local/python/3.10.13/lib/python3.10/site-packages/dagster/_core/execution/plan/execute_step.py", line 532, in core_dagster_event_sequence_for_step
    for evt in _type_check_and_store_output(step_context, user_event):
  File "/usr/local/python/3.10.13/lib/python3.10/site-packages/dagster/_core/execution/plan/execute_step.py", line 587, in _type_check_and_store_output
    for evt in _store_output(step_context, step_output_handle, output):
  File "/usr/local/python/3.10.13/lib/python3.10/site-packages/dagster/_core/execution/plan/execute_step.py", line 810, in _store_output
    for elt in iterate_with_context(
  File "/usr/local/python/3.10.13/lib/python3.10/site-packages/dagster/_utils/__init__.py", line 466, in iterate_with_context
    with context_fn():
  File "/usr/local/python/3.10.13/lib/python3.10/contextlib.py", line 153, in __exit__
    self.gen.throw(typ, value, traceback)
  File "/usr/local/python/3.10.13/lib/python3.10/site-packages/dagster/_core/execution/plan/utils.py", line 72, in op_execution_error_boundary
    raise RetryRequestedFromPolicy(

The above exception was caused by the following exception:
AttributeError: 'NoneType' object has no attribute 'write'

Stack Trace:
  File "/usr/local/python/3.10.13/lib/python3.10/site-packages/dagster/_core/execution/plan/utils.py", line 54, in op_execution_error_boundary
    yield
  File "/usr/local/python/3.10.13/lib/python3.10/site-packages/dagster/_utils/__init__.py", line 468, in iterate_with_context
    next_output = next(iterator)
  File "/usr/local/python/3.10.13/lib/python3.10/site-packages/dagster/_core/execution/plan/execute_step.py", line 800, in _gen_fn
    gen_output = output_manager.handle_output(output_context, output.value)
  File "/workspaces/practical-data-engineering/finnhub-batch-stock-pipeline/finnhub_batch_stock_pipeline/iomanagers/staging_s3_parquet_io_manager.py", line 151, in handle_output
    return self.inner_io_manager().handle_output(context, obj)
  File "/usr/local/python/3.10.13/lib/python3.10/site-packages/dagster/_core/storage/upath_io_manager.py", line 446, in handle_output
    self.dump_to_path(context=context, obj=obj, path=path)
  File "/workspaces/practical-data-engineering/finnhub-batch-stock-pipeline/finnhub_batch_stock_pipeline/iomanagers/staging_s3_parquet_io_manager.py", line 83, in dump_to_path
    obj.write.format("delta").mode('overwrite').save(pathe)

[Stage 0:>                                                          (0 + 0) / 4][Stage 0:>                                                          (0 + 4) / 4]