[32m2024-06-07 02:22:20 +0000[0m - dagster - [34mDEBUG[0m - __ASSET_JOB - def2394d-9ac6-451c-80e5-ca1ecc46156a - 10477 - LOGS_CAPTURED - Started capturing logs in process (pid: 10477).
[32m2024-06-07 02:22:20 +0000[0m - dagster - [34mDEBUG[0m - __ASSET_JOB - def2394d-9ac6-451c-80e5-ca1ecc46156a - 10477 - finnhub_US_stocks.import_stocks_def - STEP_START - Started execution of step "finnhub_US_stocks.import_stocks_def".
[32m2024-06-07 02:22:20 +0000[0m - dagster - [34mERROR[0m - [31m__ASSET_JOB - def2394d-9ac6-451c-80e5-ca1ecc46156a - 10477 - finnhub_US_stocks.import_stocks_def - STEP_FAILURE - Execution of step "finnhub_US_stocks.import_stocks_def" failed.

dagster._core.errors.DagsterExecutionStepExecutionError: Error occurred while executing op "finnhub_US_stocks.import_stocks_def"::

requests.exceptions.HTTPError: 401 Client Error: Unauthorized for url: https://finnhub.io/api/v1/stock/symbol?exchange=US&currency=USD&securityType=Common%20Stock

Stack Trace:
  File "/usr/local/python/3.10.13/lib/python3.10/site-packages/dagster/_core/execution/plan/utils.py", line 54, in op_execution_error_boundary
    yield
  File "/usr/local/python/3.10.13/lib/python3.10/site-packages/dagster/_utils/__init__.py", line 468, in iterate_with_context
    next_output = next(iterator)
  File "/usr/local/python/3.10.13/lib/python3.10/site-packages/dagster/_core/execution/plan/compute_generator.py", line 141, in _coerce_op_compute_fn_to_iterator
    result = invoke_compute_fn(
  File "/usr/local/python/3.10.13/lib/python3.10/site-packages/dagster/_core/execution/plan/compute_generator.py", line 129, in invoke_compute_fn
    return fn(context, **args_to_pass) if context_arg_provided else fn(**args_to_pass)
  File "/workspaces/practical-data-engineering/finnhub-batch-stock-pipeline/finnhub_batch_stock_pipeline/assets/graph_raw.py", line 18, in import_stocks_def
    stocks = my_conn.request(endpoint)
  File "/workspaces/practical-data-engineering/finnhub-batch-stock-pipeline/finnhub_batch_stock_pipeline/resources/__init__.py", line 58, in request
    return response.raise_for_status()
  File "/home/codespace/.local/lib/python3.10/site-packages/requests/models.py", line 1024, in raise_for_status
    raise HTTPError(http_error_msg, response=self)
[0m
